Workbook
Name Slicer_Category: #N/A
Name Slicer_Customer_Type: #N/A

Sheet Data
A1: Order ID | B1: Order Date | C1: Month | D1: Region | E1: Category | F1: Sub-Category | G1: Product Name | H1: Sales | I1: Cost | J1: Quantity | K1: Discount | L1: Profit | M1: Customer Type
A2: ORD-1001 | B2: 2023-06-17 | C2: June | D2: East | E2: Office Supplies | F2: Stapler | G2: Stapler Model-217 | H2: 939.29 | I2: 852.92 | J2: 9 | K2: 0.05 | L2: 86.37 | M2: Home Office
A3: ORD-1002 | B3: 2023-04-05 | C3: April | D3: West | E3: Technology | F3: Printer | G3: Printer Model-628 | H3: 120.25 | I3: 88.92 | J3: 6 | K3: 0 | L3: 31.33 | M3: Consumer
A4: ORD-1003 | B4: 2023-01-24 | C4: January | D4: South | E4: Technology | F4: Printer | G4: Printer Model-937 | H4: 706.1 | I4: 614.25 | J4: 4 | K4: 0.15 | L4: 91.85 | M4: Home Office
A5: ORD-1004 | B5: 2023-09-14 | C5: September | D5: West | E5: Office Supplies | F5: Binder | G5: Binder Model-166 | H5: 669.02 | I5: 582.65 | J5: 1 | K5: 0.1 | L5: 86.37 | M5: Home Office
A6: ORD-1005 | B6: 2023-02-09 | C6: February | D6: South | E6: Office Supplies | F6: Stapler | G6: Stapler Model-257 | H6: 1920.14 | I6: 1667.31 | J6: 6 | K6: 0.15 | L6: 252.83 | M6: Corporate
A7: ORD-1006 | B7: 2023-07-18 | C7: July | D7: West | E7: Technology | F7: Phone | G7: Phone Model-541 | H7: 1058.54 | I7: 805.61 | J7: 3 | K7: 0.05 | L7: 252.93 | M7: Consumer
A8: ORD-1007 | B8: 2023-07-24 | C8: July | D8: North | E8: Furniture | F8: Chair | G8: Chair Model-531 | H8: 1171.12 | I8: 1278.45 | J8: 10 | K8: 0.15 | L8: -107.33 | M8: Home Office
A9: ORD-1008 | B9: 2023-07-20 | C9: July | D9: West | E9: Office Supplies | F9: Binder | G9: Binder Model-336 | H9: 1044.52 | I9: 1040.2 | J9: 1 | K9: 0.1 | L9: 4.32 | M9: Home Office
A10: ORD-1009 | B10: 2023-05-05 | C10: May | D10: West | E10: Technology | F10: Monitor | G10: Monitor Model-188 | H10: 644.08 | I10: 691.52 | J10: 3 | K10: 0.15 | L10: -47.44 | M10: Consumer
A11: ORD-1010 | B11: 2023-08-03 | C11: August | D11: West | E11: Technology | F11: Printer | G11: Printer Model-117 | H11: 854.51 | I11: 740.16 | J11: 7 | K11: 0.1 | L11: 114.35 | M11: Home Office
A12: ORD-1011 | B12: 2023-03-25 | C12: March | D12: South | E12: Technology | F12: Laptop | G12: Laptop Model-306 | H12: 604.76 | I12: 619.27 | J12: 8 | K12: 0.1 | L12: -14.51 | M12: Consumer
A13: ORD-1012 | B13: 2023-09-24 | C13: September | D13: East | E13: Technology | F13: Phone | G13: Phone Model-683 | H13: 1783.63 | I13: 1687.91 | J13: 4 | K13: 0.2 | L13: 95.72 | M13: Corporate
... A450: ORD-1449 | B450: 2023-01-31 | C450: January | D450: West | E450: Technology | F450: Monitor | G450: Monitor Model-296 | H450: 328.19 | I450: 336.2 | J450: 5 | K450: 0.2 | L450: -8.01 | M450: Corporate
A451: ORD-1450 | B451: 2023-12-03 | C451: December | D451: North | E451: Office Supplies | G451: Stapler Model-276 | H451: 1717.82 | I451: 1750.88 | J451: 2 | K451: 0.15 | L451: -33.06 | M451: Consumer
A452: ORD-1451 | B452: 2023-01-11 | C452: January | D452: West | E452: Technology | F452: Printer | G452: Printer Model-298 | H452: 1293.11 | I452: 1148.06 | J452: 5 | K452: 0.1 | L452: 145.05 | M452: Home Office
A453: ORD-1452 | B453: 2023-06-24 | C453: June | D453: East | E453: Office Supplies | F453: Paper | G453: Paper Model-242 | H453: 782.28 | I453: 654.76 | J453: 9 | K453: 0 | L453: 127.52 | M453: Consumer
A454: ORD-1453 | B454: 2023-10-15 | C454: October | D454: East | E454: Technology | F454: Phone | G454: Phone Model-128 | H454: 108.96 | I454: 114.96 | J454: 7 | K454: 0.15 | L454: -6 | M454: Home Office
A455: ORD-1454 | B455: 2023-01-31 | C455: January | D455: East | E455: Technology | F455: Laptop | G455: Laptop Model-515 | H455: 322.65 | I455: 317.56 | J455: 9 | K455: 0.15 | L455: 5.09 | M455: Corporate
A456: ORD-1455 | B456: 2023-10-05 | C456: October | D456: East | E456: Technology | F456: Monitor | G456: Monitor Model-991 | H456: 1755.31 | I456: 1937.3 | J456: 9 | K456: 0.2 | L456: -181.99 | M456: Consumer
A457: ORD-1456 | B457: 2023-04-26 | C457: April | D457: South | E457: Furniture | F457: Bookcase | G457: Bookcase Model-574 | H457: 1494.71 | I457: 1464.76 | J457: 7 | K457: 0.2 | L457: 29.95 | M457: Corporate
A458: ORD-1457 | B458: 2023-03-22 | C458: March | D458: South | E458: Office Supplies | F458: Paper | G458: Paper Model-754 | H458: 1206.77 | I458: 1368.03 | J458: 2 | K458: 0.2 | L458: -161.26 | M458: Home Office
A459: ORD-1458 | B459: 2023-03-16 | C459: March | D459: East | E459: Office Supplies | F459: Stapler | G459: Stapler Model-208 | H459: 310.82 | I459: 288.28 | J459: 3 | K459: 0.05 | L459: 22.54 | M459: Home Office
A460: ORD-1459 | B460: 2023-05-21 | C460: May | D460: North | E460: Furniture | F460: Bookcase | G460: Bookcase Model-580 | H460: 1808.77 | I460: 1582.09 | J460: 10 | K460: 0.05 | L460: 226.68 | M460: Corporate
A461: ORD-1460 | B461: 2023-05-27 | C461: May | D461: West | E461: Office Supplies | F461: Pen | G461: Pen Model-665 | H461: 1179.01 | I461: 890.83 | J461: 6 | K461: 0 | L461: 288.18 | M461: Home Office
A462: ORD-1461 | B462: 2023-09-12 | C462: September | D462: West | E462: Office Supplies | F462: Stapler | G462: Stapler Model-335 | H462: 525.74 | I462: 537.97 | J462: 6 | K462: 0.2 | L462: -12.23 | M462: Corporate
A463: ORD-1462 | B463: 2023-12-04 | C463: December | D463: North | E463: Furniture | F463: Sofa | G463: Sofa Model-225 | H463: 1878.55 | I463: 1368.9 | J463: 9 | K463: 0 | L463: 509.65 | M463: Corporate
... A501: ORD-1500 | B501: 2023-12-03 | C501: December | D501: East | E501: Technology | F501: Laptop | G501: Laptop Model-867 | H501: 1153.7 | I501: 1045.48 | J501: 9 | K501: 0.05 | L501: 108.22 | M501: Home Office

Sheet Qustions 
A1: PROJECT THEME: “Sales & Profit Analytics Dashboard for a Retail Company”
A2: A. Data Cleaning & Transformation | D2: B. Exploratory Data Analysis (EDA)
A4: 1. Identify and handle missing or duplicate values. | D4: 6. Find total Sales, Profit, and Quantity by:
A6: 2. Create a new column “Profit Margin = Profit / Sales”.
A8: 3. Extract Month and Year from the “Order Date”. | D8: Region
A10: 4. Use Excel formulas to categorize Sales Volume into: | D10: Category
D12: Customer Type
A14: Low (<500), Medium (500–1000), High (>1000). | D14: 7. Determine Top 5 Profitable Products and Bottom 5.
A16: 5. Check for outliers using IQR or Box Plot method in Excel. | D16: 8. Analyze Profit Margin by Region using Pivot Tables.
D18: 9. Create a correlation heatmap using Excel’s Data Analysis Toolpak (Sales, Profit, Discount, Quantity).
D20: 10. Find which month has the highest average profit margin.
D22: Extra Qustion | F22: Find which customer segment gives the highest profit on average.
F23: Find the average profit for each product category.
F24: Find the month with the highest total sales.
F25: Create a reusable LAMBDA function for average profit per group
A27: C. Advanced Analysis | D27: D. Dashboard Tasks (Visualization)
A29: 11. Build a Forecast of next 3 months’ sales using: | D29: 16. Create a Dynamic Dashboard in Excel using:
A31: Excel’s Forecast.ETS or Trendline regression. | D31: Slicers for Region, Category, Customer Type
A33: 12. Use Pivot Charts to analyze: | D33: KPIs (Total Sales, Avg Profit, Profit Margin)
A35: Sales trend by month | D35: Line chart (Sales trend)
A37: Profit comparison by category | D37: Bar chart (Profit by Category)
A39: 13. Calculate Month-over-Month (MoM) Growth % in Sales and Profit. | D39: Pie chart (Sales by Region)
A41: 14. Identify Top 10% customers contributing to total sales (Pareto principle). | D41: 17. Add conditional formatting for:
A43: 15. Perform “What-If Analysis”: | D43: Highlighting negative profits in red.
A45: If discount increases by 5%, how much will profit reduce? | D45: High margin products in green.

Sheet Data Cleaning & Transf
A1: Order ID | B1: Order Date | C1: Month - Year | D1: Region | E1: Category | F1: Sub-Category | G1: Product Name | H1: Sales | I1: Quantity | J1: Discount | K1: Profit | L1: Customer Type | M1: Profit Margin | N1: Sales Volume
A2: ORD-1001 | B2: 2023-06-17 | C2: =TEXT(B2,"MM-YYYY") -> 06-2023 | D2: East | E2: Office Supplies | F2: Stapler | G2: Stapler Model-217 | H2: 939.29 | I2: 9 | J2: 0.05 | K2: 2.5 | L2: Home Office | M2: =K2/H2 -> 0.0026615848 | N2: {=_xlfn.IFS('Data Cleaning & Transf'!H2<500,"LOW",AND('Data Cleaning & Transf'!H2 >500,'Data Cleaning & Transf'!H2<1000),"Medium",'Data Cleaning & Transf'!H2>1000,"High")} -> Medium
A3: ORD-1002 | B3: 2023-04-05 | C3: =TEXT(B3,"MM-YYYY") -> 04-2023 | D3: West | E3: Technology | F3: Printer | G3: Printer Model-628 | H3: 120.25 | I3: 6 | J3: 0 | K3: 31.33 | L3: Consumer | M3: =K3/H3 -> 0.26054054 | N3: {=_xlfn.IFS('Data Cleaning & Transf'!H3<500,"LOW",AND('Data Cleaning & Transf'!H3 >500,'Data Cleaning & Transf'!H3<1000),"Medium",'Data Cleaning & Transf'!H3>1000,"High")} -> LOW
A4: ORD-1003 | B4: 2023-01-24 | C4: =TEXT(B4,"MM-YYYY") -> 01-2023 | D4: South | E4: Technology | F4: Printer | G4: Printer Model-937 | H4: 706.1 | I4: 4 | J4: 0.15 | K4: 91.85 | L4: Home Office | M4: =K4/H4 -> 0.13008073 | N4: {=_xlfn.IFS('Data Cleaning & Transf'!H4<500,"LOW",AND('Data Cleaning & Transf'!H4 >500,'Data Cleaning & Transf'!H4<1000),"Medium",'Data Cleaning & Transf'!H4>1000,"High")} -> Medium
A5: ORD-1004 | B5: 2023-09-14 | C5: =TEXT(B5,"MM-YYYY") -> 09-2023 | D5: West | E5: Office Supplies | F5: Binder | G5: Binder Model-166 | H5: 669.02 | I5: 1 | J5: 0.1 | K5: 86.37 | L5: Home Office | M5: =K5/H5 -> 0.12909928 | N5: {=_xlfn.IFS('Data Cleaning & Transf'!H5<500,"LOW",AND('Data Cleaning & Transf'!H5 >500,'Data Cleaning & Transf'!H5<1000),"Medium",'Data Cleaning & Transf'!H5>1000,"High")} -> Medium
A6: ORD-1005 | B6: 2023-02-09 | C6: =TEXT(B6,"MM-YYYY") -> 02-2023 | D6: South | E6: Office Supplies | F6: Stapler | G6: Stapler Model-257 | H6: 1920.14 | I6: 6 | J6: 0.15 | K6: 252.83 | L6: Corporate | M6: =K6/H6 -> 0.13167269 | N6: {=_xlfn.IFS('Data Cleaning & Transf'!H6<500,"LOW",AND('Data Cleaning & Transf'!H6 >500,'Data Cleaning & Transf'!H6<1000),"Medium",'Data Cleaning & Transf'!H6>1000,"High")} -> High
A7: ORD-1006 | B7: 2023-07-18 | C7: =TEXT(B7,"MM-YYYY") -> 07-2023 | D7: West | E7: Technology | F7: Phone | G7: Phone Model-541 | H7: 1058.54 | I7: 3 | J7: 0.05 | K7: 252.93 | L7: Consumer | M7: =K7/H7 -> 0.23894232 | N7: {=_xlfn.IFS('Data Cleaning & Transf'!H7<500,"LOW",AND('Data Cleaning & Transf'!H7 >500,'Data Cleaning & Transf'!H7<1000),"Medium",'Data Cleaning & Transf'!H7>1000,"High")} -> High
A8: ORD-1007 | B8: 2023-07-24 | C8: =TEXT(B8,"MM-YYYY") -> 07-2023 | D8: North | E8: Furniture | F8: Chair | G8: Chair Model-531 | H8: 1171.12 | I8: 10 | J8: 0.15 | K8: -107.33 | L8: Home Office | M8: =K8/H8 -> -0.091647312 | N8: {=_xlfn.IFS('Data Cleaning & Transf'!H8<500,"LOW",AND('Data Cleaning & Transf'!H8 >500,'Data Cleaning & Transf'!H8<1000),"Medium",'Data Cleaning & Transf'!H8>1000,"High")} -> High
A9: ORD-1008 | B9: 2023-07-20 | C9: =TEXT(B9,"MM-YYYY") -> 07-2023 | D9: West | E9: Office Supplies | F9: Binder | G9: Binder Model-336 | H9: 1044.52 | I9: 1 | J9: 0.1 | K9: 4.32 | L9: Home Office | M9: =K9/H9 -> 0.004135871 | N9: {=_xlfn.IFS('Data Cleaning & Transf'!H9<500,"LOW",AND('Data Cleaning & Transf'!H9 >500,'Data Cleaning & Transf'!H9<1000),"Medium",'Data Cleaning & Transf'!H9>1000,"High")} -> High
A10: ORD-1009 | B10: 2023-05-05 | C10: =TEXT(B10,"MM-YYYY") -> 05-2023 | D10: West | E10: Technology | F10: Monitor | G10: Monitor Model-188 | H10: 644.08 | I10: 3 | J10: 0.15 | K10: -47.44 | L10: Consumer | M10: =K10/H10 -> -0.073655447 | N10: {=_xlfn.IFS('Data Cleaning & Transf'!H10<500,"LOW",AND('Data Cleaning & Transf'!H10 >500,'Data Cleaning & Transf'!H10<1000),"Medium",'Data Cleaning & Transf'!H10>1000,"High")} -> Medium
A11: ORD-1010 | B11: 2023-08-03 | C11: =TEXT(B11,"MM-YYYY") -> 08-2023 | D11: West | E11: Technology | F11: Printer | G11: Printer Model-117 | H11: 854.51 | I11: 7 | J11: 0.1 | K11: 114.35 | L11: Home Office | M11: =K11/H11 -> 0.13381938 | N11: {=_xlfn.IFS('Data Cleaning & Transf'!H11<500,"LOW",AND('Data Cleaning & Transf'!H11 >500,'Data Cleaning & Transf'!H11<1000),"Medium",'Data Cleaning & Transf'!H11>1000,"High")} -> Medium
A12: ORD-1011 | B12: 2023-03-25 | C12: =TEXT(B12,"MM-YYYY") -> 03-2023 | D12: South | E12: Technology | F12: Laptop | G12: Laptop Model-306 | H12: 604.76 | I12: 8 | J12: 0.1 | K12: -14.51 | L12: Consumer | M12: =K12/H12 -> -0.023992989 | N12: {=_xlfn.IFS('Data Cleaning & Transf'!H12<500,"LOW",AND('Data Cleaning & Transf'!H12 >500,'Data Cleaning & Transf'!H12<1000),"Medium",'Data Cleaning & Transf'!H12>1000,"High")} -> Medium
A13: ORD-1012 | B13: 2023-09-24 | C13: =TEXT(B13,"MM-YYYY") -> 09-2023 | D13: East | E13: Technology | F13: Phone | G13: Phone Model-683 | H13: 1783.63 | I13: 4 | J13: 0.2 | K13: 95.72 | L13: Corporate | M13: =K13/H13 -> 0.053665839 | N13: {=_xlfn.IFS('Data Cleaning & Transf'!H13<500,"LOW",AND('Data Cleaning & Transf'!H13 >500,'Data Cleaning & Transf'!H13<1000),"Medium",'Data Cleaning & Transf'!H13>1000,"High")} -> High
... A20: ORD-1019 | B20: 2023-07-31 | C20: =TEXT(B20,"MM-YYYY") -> 07-2023 | D20: South | E20: Furniture | F20: Table | G20: Table Model-923 | H20: 545.57 | I20: 9 | J20: 0.1 | K20: 64.61 | L20: Corporate | M20: =K20/H20 -> 0.1184266 | N20: {=_xlfn.IFS('Data Cleaning & Transf'!H20<500,"LOW",AND('Data Cleaning & Transf'!H20 >500,'Data Cleaning & Transf'!H20<1000),"Medium",'Data Cleaning & Transf'!H20>1000,"High")} -> Medium
A21: ORD-1020 | B21: 2023-04-23 | C21: =TEXT(B21,"MM-YYYY") -> 04-2023 | D21: North | E21: Furniture | F21: Chair | G21: Chair Model-407 | H21: 1957.63 | I21: 3 | J21: 0.2 | K21: 133.24 | L21: Home Office | M21: =K21/H21 -> 0.068061891 | N21: {=_xlfn.IFS('Data Cleaning & Transf'!H21<500,"LOW",AND('Data Cleaning & Transf'!H21 >500,'Data Cleaning & Transf'!H21<1000),"Medium",'Data Cleaning & Transf'!H21>1000,"High")} -> High | O21: IQR
A22: ORD-1021 | B22: 2023-10-23 | C22: =TEXT(B22,"MM-YYYY") -> 10-2023 | D22: East | E22: Technology | F22: Laptop | G22: Laptop Model-863 | H22: 110.63 | I22: 1 | J22: 0.2 | K22: -8.59 | L22: Corporate | M22: =K22/H22 -> -0.077646208 | N22: {=_xlfn.IFS('Data Cleaning & Transf'!H22<500,"LOW",AND('Data Cleaning & Transf'!H22 >500,'Data Cleaning & Transf'!H22<1000),"Medium",'Data Cleaning & Transf'!H22>1000,"High")} -> LOW
A23: ORD-1022 | B23: 2023-06-20 | C23: =TEXT(B23,"MM-YYYY") -> 06-2023 | D23: South | E23: Technology | F23: Phone | G23: Phone Model-925 | H23: 1061.76 | I23: 10 | J23: 0.05 | K23: 33.81 | L23: Consumer | M23: =K23/H23 -> 0.031843354 | N23: {=_xlfn.IFS('Data Cleaning & Transf'!H23<500,"LOW",AND('Data Cleaning & Transf'!H23 >500,'Data Cleaning & Transf'!H23<1000),"Medium",'Data Cleaning & Transf'!H23>1000,"High")} -> High | O23: Q1 | P23: =_xlfn.QUARTILE.INC(H2:H501,1) -> 535.215
A24: ORD-1023 | B24: 2023-08-10 | C24: =TEXT(B24,"MM-YYYY") -> 08-2023 | D24: East | E24: Technology | F24: Monitor | G24: Monitor Model-275 | H24: 1293.34 | I24: 6 | J24: 0.15 | K24: 187.33 | L24: Home Office | M24: =K24/H24 -> 0.14484204 | N24: {=_xlfn.IFS('Data Cleaning & Transf'!H24<500,"LOW",AND('Data Cleaning & Transf'!H24 >500,'Data Cleaning & Transf'!H24<1000),"Medium",'Data Cleaning & Transf'!H24>1000,"High")} -> High | O24: Q3 | P24: =_xlfn.QUARTILE.INC(H2:H501,3) -> 1441.42
A25: ORD-1024 | B25: 2023-10-28 | C25: =TEXT(B25,"MM-YYYY") -> 10-2023 | D25: North | E25: Furniture | F25: Chair | G25: Chair Model-449 | H25: 1215.31 | I25: 6 | J25: 0.15 | K25: 113.79 | L25: Consumer | M25: =K25/H25 -> 0.093630432 | N25: {=_xlfn.IFS('Data Cleaning & Transf'!H25<500,"LOW",AND('Data Cleaning & Transf'!H25 >500,'Data Cleaning & Transf'!H25<1000),"Medium",'Data Cleaning & Transf'!H25>1000,"High")} -> High
A26: ORD-1025 | B26: 2023-06-28 | C26: =TEXT(B26,"MM-YYYY") -> 06-2023 | D26: East | E26: Office Supplies | F26: Binder | G26: Binder Model-671 | H26: 531.03 | I26: 1 | J26: 0.05 | K26: 70.01 | L26: Consumer | M26: =K26/H26 -> 0.13183813 | N26: {=_xlfn.IFS('Data Cleaning & Transf'!H26<500,"LOW",AND('Data Cleaning & Transf'!H26 >500,'Data Cleaning & Transf'!H26<1000),"Medium",'Data Cleaning & Transf'!H26>1000,"High")} -> Medium | O26: IQR | P26: =P24-P23 -> 906.205
A27: ORD-1026 | B27: 2023-02-03 | C27: =TEXT(B27,"MM-YYYY") -> 02-2023 | D27: East | E27: Technology | F27: Phone | G27: Phone Model-832 | H27: 1990.61 | I27: 5 | J27: 0.15 | K27: -89.79 | L27: Consumer | M27: =K27/H27 -> -0.045106776 | N27: {=_xlfn.IFS('Data Cleaning & Transf'!H27<500,"LOW",AND('Data Cleaning & Transf'!H27 >500,'Data Cleaning & Transf'!H27<1000),"Medium",'Data Cleaning & Transf'!H27>1000,"High")} -> High
A28: ORD-1027 | B28: 2023-02-22 | C28: =TEXT(B28,"MM-YYYY") -> 02-2023 | D28: West | E28: Technology | F28: Phone | G28: Phone Model-302 | H28: 1096.65 | I28: 9 | J28: 0.1 | K28: 0.96 | L28: Consumer | M28: =K28/H28 -> 0.00087539324 | N28: {=_xlfn.IFS('Data Cleaning & Transf'!H28<500,"LOW",AND('Data Cleaning & Transf'!H28 >500,'Data Cleaning & Transf'!H28<1000),"Medium",'Data Cleaning & Transf'!H28>1000,"High")} -> High
A29: ORD-1028 | B29: 2023-12-27 | C29: =TEXT(B29,"MM-YYYY") -> 12-2023 | D29: North | E29: Furniture | F29: Sofa | G29: Sofa Model-862 | H29: 517.61 | I29: 10 | J29: 0.2 | K29: -72.71 | L29: Home Office | M29: =K29/H29 -> -0.14047256 | N29: {=_xlfn.IFS('Data Cleaning & Transf'!H29<500,"LOW",AND('Data Cleaning & Transf'!H29 >500,'Data Cleaning & Transf'!H29<1000),"Medium",'Data Cleaning & Transf'!H29>1000,"High")} -> Medium | O29: FIND LOWERBOND | P29: =P23 - 1.5*P26 -> -824.0925
A30: ORD-1029 | B30: 2023-03-01 | C30: =TEXT(B30,"MM-YYYY") -> 03-2023 | D30: North | E30: Technology | F30: Printer | G30: Printer Model-415 | H30: 152.88 | I30: 8 | J30: 0.2 | K30: -19.48 | L30: Home Office | M30: =K30/H30 -> -0.1274202 | N30: {=_xlfn.IFS('Data Cleaning & Transf'!H30<500,"LOW",AND('Data Cleaning & Transf'!H30 >500,'Data Cleaning & Transf'!H30<1000),"Medium",'Data Cleaning & Transf'!H30>1000,"High")} -> LOW | O30: FIND UPPERBOND | P30: =P24 - 1.5*P26 -> 82.1125
A31: ORD-1030 | B31: 2023-08-04 | C31: =TEXT(B31,"MM-YYYY") -> 08-2023 | D31: North | E31: Office Supplies | F31: Paper | G31: Paper Model-341 | H31: 1742.66 | I31: 2 | J31: 0 | K31: 370.73 | L31: Home Office | M31: =K31/H31 -> 0.212738 | N31: {=_xlfn.IFS('Data Cleaning & Transf'!H31<500,"LOW",AND('Data Cleaning & Transf'!H31 >500,'Data Cleaning & Transf'!H31<1000),"Medium",'Data Cleaning & Transf'!H31>1000,"High")} -> High
A32: ORD-1031 | B32: 2023-01-14 | C32: =TEXT(B32,"MM-YYYY") -> 01-2023 | D32: West | E32: Office Supplies | F32: Pen | G32: Pen Model-876 | H32: 567.23 | I32: 10 | J32: 0.1 | K32: 65.24 | L32: Home Office | M32: =K32/H32 -> 0.11501507 | N32: {=_xlfn.IFS('Data Cleaning & Transf'!H32<500,"LOW",AND('Data Cleaning & Transf'!H32 >500,'Data Cleaning & Transf'!H32<1000),"Medium",'Data Cleaning & Transf'!H32>1000,"High")} -> Medium
A33: ORD-1032 | B33: 2023-06-07 | C33: =TEXT(B33,"MM-YYYY") -> 06-2023 | D33: West | E33: Office Supplies | F33: Stapler | G33: Stapler Model-315 | H33: 611.9 | I33: 10 | J33: 0.05 | K33: 136.64 | L33: Corporate | M33: =K33/H33 -> 0.22330446 | N33: {=_xlfn.IFS('Data Cleaning & Transf'!H33<500,"LOW",AND('Data Cleaning & Transf'!H33 >500,'Data Cleaning & Transf'!H33<1000),"Medium",'Data Cleaning & Transf'!H33>1000,"High")} -> Medium
A34: ORD-1033 | B34: 2023-04-13 | C34: =TEXT(B34,"MM-YYYY") -> 04-2023 | D34: South | E34: Technology | F34: Laptop | G34: Laptop Model-762 | H34: 1839.96 | I34: 3 | J34: 0.2 | K34: -123.42 | L34: Home Office | M34: =K34/H34 -> -0.067077545 | N34: {=_xlfn.IFS('Data Cleaning & Transf'!H34<500,"LOW",AND('Data Cleaning & Transf'!H34 >500,'Data Cleaning & Transf'!H34<1000),"Medium",'Data Cleaning & Transf'!H34>1000,"High")} -> High
A35: ORD-1034 | B35: 2023-11-18 | C35: =TEXT(B35,"MM-YYYY") -> 11-2023 | D35: East | E35: Furniture | F35: Chair | G35: Chair Model-681 | H35: 1795.83 | I35: 3 | J35: 0.15 | K35: -174.78 | L35: Consumer | M35: =K35/H35 -> -0.097325471 | N35: {=_xlfn.IFS('Data Cleaning & Transf'!H35<500,"LOW",AND('Data Cleaning & Transf'!H35 >500,'Data Cleaning & Transf'!H35<1000),"Medium",'Data Cleaning & Transf'!H35>1000,"High")} -> High
A36: ORD-1035 | B36: 2023-03-19 | C36: =TEXT(B36,"MM-YYYY") -> 03-2023 | D36: West | E36: Office Supplies | F36: Binder | G36: Binder Model-649 | H36: 1893.59 | I36: 8 | J36: 0.15 | K36: -160.47 | L36: Home Office | M36: =K36/H36 -> -0.084743794 | N36: {=_xlfn.IFS('Data Cleaning & Transf'!H36<500,"LOW",AND('Data Cleaning & Transf'!H36 >500,'Data Cleaning & Transf'!H36<1000),"Medium",'Data Cleaning & Transf'!H36>1000,"High")} -> High
A37: ORD-1036 | B37: 2023-08-13 | C37: =TEXT(B37,"MM-YYYY") -> 08-2023 | D37: South | E37: Office Supplies | F37: Paper | G37: Paper Model-801 | H37: 847.33 | I37: 3 | J37: 0.1 | K37: -26.89 | L37: Consumer | M37: =K37/H37 -> -0.031734979 | N37: {=_xlfn.IFS('Data Cleaning & Transf'!H37<500,"LOW",AND('Data Cleaning & Transf'!H37 >500,'Data Cleaning & Transf'!H37<1000),"Medium",'Data Cleaning & Transf'!H37>1000,"High")} -> Medium
A38: ORD-1037 | B38: 2023-06-23 | C38: =TEXT(B38,"MM-YYYY") -> 06-2023 | D38: South | E38: Technology | F38: Laptop | G38: Laptop Model-960 | H38: 1777.11 | I38: 9 | J38: 0.15 | K38: -1.36 | L38: Consumer | M38: =K38/H38 -> -0.00076528746 | N38: {=_xlfn.IFS('Data Cleaning & Transf'!H38<500,"LOW",AND('Data Cleaning & Transf'!H38 >500,'Data Cleaning & Transf'!H38<1000),"Medium",'Data Cleaning & Transf'!H38>1000,"High")} -> High
A39: ORD-1038 | B39: 2023-03-03 | C39: =TEXT(B39,"MM-YYYY") -> 03-2023 | D39: West | E39: Furniture | F39: Table | G39: Table Model-132 | H39: 1436.59 | I39: 3 | J39: 0 | K39: 316.05 | L39: Consumer | M39: =K39/H39 -> 0.22000014 | N39: {=_xlfn.IFS('Data Cleaning & Transf'!H39<500,"LOW",AND('Data Cleaning & Transf'!H39 >500,'Data Cleaning & Transf'!H39<1000),"Medium",'Data Cleaning & Transf'!H39>1000,"High")} -> High
A40: ORD-1039 | B40: 2023-07-22 | C40: =TEXT(B40,"MM-YYYY") -> 07-2023 | D40: South | E40: Office Supplies | F40: Stapler | G40: Stapler Model-392 | H40: 819.42 | I40: 8 | J40: 0.15 | K40: 118.82 | L40: Corporate | M40: =K40/H40 -> 0.145005 | N40: {=_xlfn.IFS('Data Cleaning & Transf'!H40<500,"LOW",AND('Data Cleaning & Transf'!H40 >500,'Data Cleaning & Transf'!H40<1000),"Medium",'Data Cleaning & Transf'!H40>1000,"High")} -> Medium
A41: ORD-1040 | B41: 2023-12-21 | C41: =TEXT(B41,"MM-YYYY") -> 12-2023 | D41: North | E41: Technology | F41: Laptop | G41: Laptop Model-214 | H41: 1411.03 | I41: 1 | J41: 0.2 | K41: -200.38 | L41: Corporate | M41: =K41/H41 -> -0.14200974 | N41: {=_xlfn.IFS('Data Cleaning & Transf'!H41<500,"LOW",AND('Data Cleaning & Transf'!H41 >500,'Data Cleaning & Transf'!H41<1000),"Medium",'Data Cleaning & Transf'!H41>1000,"High")} -> High
A42: ORD-1041 | B42: 2023-08-11 | C42: =TEXT(B42,"MM-YYYY") -> 08-2023 | D42: West | E42: Technology | F42: Printer | G42: Printer Model-989 | H42: 1212.15 | I42: 5 | J42: 0.1 | K42: 43.72 | L42: Corporate | M42: =K42/H42 -> 0.036068143 | N42: {=_xlfn.IFS('Data Cleaning & Transf'!H42<500,"LOW",AND('Data Cleaning & Transf'!H42 >500,'Data Cleaning & Transf'!H42<1000),"Medium",'Data Cleaning & Transf'!H42>1000,"High")} -> High
... A501: ORD-1500 | B501: 2023-12-03 | C501: =TEXT(B501,"MM-YYYY") -> 12-2023 | D501: East | E501: Technology | F501: Laptop | G501: Laptop Model-867 | H501: 1153.7 | I501: 9 | J501: 0.05 | K501: 108.22 | L501: Home Office | M501: =K501/H501 -> 0.093802548 | N501: {=_xlfn.IFS('Data Cleaning & Transf'!H501<500,"LOW",AND('Data Cleaning & Transf'!H501 >500,'Data Cleaning & Transf'!H501<1000),"Medium",'Data Cleaning & Transf'!H501>1000,"High")} -> High

Sheet EDA
A1: Region | B1: Category | C1: Customer Type | D1: Sum of Quantity | E1: Sum of Sales
A2: East | B2: Furniture | C2: Consumer | D2: 46 | E2: 13536.97 | G2: Determine Top 5 Profitable Products
A3: East | B3: Furniture | C3: Corporate | D3: 42 | E3: 11934.68 | G3: {=INDEX(Data!G2:G501,MATCH(LARGE(SUMIF(Data!G2:G501,Data!G2:G501,Data!L2:L501),{1,2,3,4}),SUMIF(Data!G2:G501,Data!G2:G501,Data!L2:L501),0))} -> Monitor Model-975 | H3: Monitor Model-975 | I3: Monitor Model-975 | J3: Bookcase Model-618
A4: East | B4: Furniture | C4: Home Office | D4: 79 | E4: 13351.33
A5: East | B5: Office Supplies | C5: Consumer | D5: 62 | E5: 14638.48 | G5: Bottom 5
A6: East | B6: Office Supplies | C6: Corporate | D6: 73 | E6: 12285.24 | G6: {=INDEX(Data!G2:G501, MATCH(SMALL(SUMIF(Data!G2:G501, Data!G2:G501, Data!L2:L501), ROW(1:5)), SUMIF(Data!G2:G501, Data!G2:G501, Data!L2:L501), 0))} -> Printer Model-425
A7: East | B7: Office Supplies | C7: Home Office | D7: 54 | E7: 12662.77 | G7: Stapler Model-869
A8: East | B8: Technology | C8: Consumer | D8: 65 | E8: 13501.59 | G8: Pen Model-630
A9: East | B9: Technology | C9: Corporate | D9: 106 | E9: 18677.65 | G9: Laptop Model-214
A10: East | B10: Technology | C10: Home Office | D10: 88 | E10: 12773.95 | G10: Pen Model-819
A11: North | B11: Furniture | C11: Consumer | D11: 96 | E11: 13519.37
A12: North | B12: Furniture | C12: Corporate | D12: 90 | E12: 18895.06
A13: North | B13: Furniture | C13: Home Office | D13: 121 | E13: 21742.4 | G13: Analyze Profit Margin by Region using Pivot Tables.
A14: North | B14: Office Supplies | C14: Consumer | D14: 87 | E14: 14398.15 | G14: Region | H14: Profit
A15: North | B15: Office Supplies | C15: Corporate | D15: 46 | E15: 10707.94 | G15: East | H15: 9180.09
A16: North | B16: Office Supplies | C16: Home Office | D16: 85 | E16: 16345.78 | G16: North | H16: 7926.06
A17: North | B17: Technology | C17: Consumer | D17: 56 | E17: 7726.25 | G17: South | H17: 7338.09
A18: North | B18: Technology | C18: Corporate | D18: 68 | E18: 9150.13 | G18: West | H18: 9653.97
A19: North | B19: Technology | C19: Home Office | D19: 57 | E19: 10780.76
A20: South | B20: Furniture | C20: Consumer | D20: 91 | E20: 18377.99
A21: South | B21: Furniture | C21: Corporate | D21: 45 | E21: 6401.77 | G21: Create a correlation heatmap using Excel’s Data Analysis Toolpak (Sales, Profit, Discount, Quantity).
A22: South | B22: Furniture | C22: Home Office | D22: 62 | E22: 13643.58 | H22: Sales | I22: Quantity | J22: Discount | K22: Profit
A23: South | B23: Office Supplies | C23: Consumer | D23: 73 | E23: 12752.79 | G23: Sales | H23: 1
A24: South | B24: Office Supplies | C24: Corporate | D24: 66 | E24: 14688.01 | G24: Quantity | H24: -0.012895177 | I24: 1
A25: South | B25: Office Supplies | C25: Home Office | D25: 62 | E25: 13906.47 | G25: Discount | H25: 0.060797248 | I25: -0.01457859 | J25: 1
A26: South | B26: Technology | C26: Consumer | D26: 74 | E26: 15744.41 | G26: Profit | H26: 0.2479714 | I26: 0.02091281 | J26: -0.56919815 | K26: 1
A27: South | B27: Technology | C27: Corporate | D27: 108 | E27: 21153.67
A28: South | B28: Technology | C28: Home Office | D28: 90 | E28: 16020.43
A29: West | B29: Furniture | C29: Consumer | D29: 76 | E29: 12520.21
A30: West | B30: Furniture | C30: Corporate | D30: 85 | E30: 13876.95 | G30: Find which month has the highest average profit margin. | K30: Find the average profit for each product category.
A31: West | B31: Furniture | C31: Home Office | D31: 58 | E31: 6747.67 | G31: =INDEX('Pviot(advance Analysts) '!A4:A16,MATCH(MAX('Pviot(advance Analysts) '!B4:B16),'Pviot(advance Analysts) '!B4:B16,0)) -> February | K31: {=_xlfn.LET( _xlpm.profit, Data!L2:L501, _xlpm.product, Data!G2:G501, _xlpm.uni_product, Data!G2:G501, _xlpm.avg, _xlfn.MAP(_xlpm.uni_product,_xlfn.LAMBDA(_xlpm.x,AVERAGEIF(_xlpm.product,_xlpm.x,_xlpm.profit))),_xlfn.HSTACK(_xlpm.uni_product,_xlpm.avg))} -> Stapler Model-217 | L31: 86.37
A32: West | B32: Office Supplies | C32: Consumer | D32: 51 | E32: 8927.91 | K32: Printer Model-628 | L32: 31.33
A33: West | B33: Office Supplies | C33: Corporate | D33: 84 | E33: 12344.46 | G33: Find which customer segment gives the highest profit on average. | K33: Printer Model-937 | L33: 91.85
A34: West | B34: Office Supplies | C34: Home Office | D34: 125 | E34: 23462.33 | G34: {=_xlfn.LET(_xlpm.Category,Data!E2:E501,_xlpm.profit,Data!L2:L501,_xlpm.unicat,_xlfn.UNIQUE(_xlpm.Category),_xlpm.avg_cat,_xlfn.MAP(_xlpm.unicat,_xlfn.LAMBDA(_xlpm.m,AVERAGEIF(_xlpm.Category,_xlpm.m,_xlpm.profit))),INDEX(_xlpm.unicat,MATCH(MAX(_xlpm.avg_cat),_xlpm.avg_cat,0)))} -> Technology | K34: Binder Model-166 | L34: 86.37
A35: West | B35: Technology | C35: Consumer | D35: 93 | E35: 14378.48 | K35: Stapler Model-257 | L35: 252.83
A36: West | B36: Technology | C36: Corporate | D36: 62 | E36: 15953.99 | G36: Identify the region with the highest average discount. | K36: Phone Model-541 | L36: 252.93
A37: West | B37: Technology | C37: Home Office | D37: 59 | E37: 11051.71 | G37: {=_xlfn.LET(_xlpm.Discount,Data!K2:K501, _xlpm.region,Data!D2:D501, _xlpm.uniq_region,_xlfn.UNIQUE(_xlpm.region), _xlpm.avg_table,_xlfn.MAP(_xlpm.uniq_region,_xlfn.LAMBDA(_xlpm.m,AVERAGEIF(_xlpm.region,_xlpm.m,_xlpm.Discount))), _xlpm.max_id,MATCH(MAX(_xlpm.avg_table),_xlpm.avg_table,0), INDEX(_xlpm.uniq_region,_xlpm.max_id))} -> North | K37: Chair Model-531 | L37: -107.33
K38: Binder Model-336 | L38: 4.32
G39: Find top-performing category based on average profit margin. | K39: Monitor Model-188 | L39: -47.44
G40: {=_xlfn.LET(_xlpm.profit, Data!L2:L501, _xlpm.Sale, Data!H2:H501, _xlpm.Profit_margin, _xlpm.profit/_xlpm.Sale*100, _xlpm.Category,Data!E2:E501, _xlpm.uni_cat, _xlfn.UNIQUE(_xlpm.Category), _xlpm.table, _xlfn.MAP(_xlpm.uni_cat,_xlfn.LAMBDA(_xlpm.x,MAX(_xlpm.Profit_margin))), _xlpm.m_idex, MATCH(MAX(_xlpm.table),_xlpm.table,0), INDEX(_xlpm.uni_cat,_xlpm.m_idex))} -> Office Supplies | K40: Printer Model-117 | L40: 114.35
...

Sheet Advanced Analysis
B2: 12. Use Pivot Charts to analyze:
B23: 13. Calculate Month-over-Month (MoM) Growth % in Sales and Profit
B26: Month | C26: Sum of Sales | D26: Sum of Profit | E26: Sale Growth | F26: Profit Growth
B27: January | C27: 43951.5 | D27: 3679.03
B28: February | C28: 34016.74 | D28: 2644.13 | E28: =(C28-C27)/C27 -> -0.22603916 | F28: =(D28-D27)/D27 -> -0.28129697
B29: March | C29: 52376.79 | D29: 3872.15 | E29: =(C29-C28)/C28 -> 0.53973573 | F29: =(D29-D28)/D28 -> 0.46443254
B30: April | C30: 35133.75 | D30: 2847.86 | E30: =(C30-C29)/C29 -> -0.32921147 | F30: =(D30-D29)/D29 -> -0.26452746
B31: May | C31: 34616.54 | D31: 2197.09 | E31: =(C31-C30)/C30 -> -0.014721173 | F31: =(D31-D30)/D30 -> -0.22851194
B32: June | C32: 42426.91 | D32: 2204.54 | E32: =(C32-C31)/C31 -> 0.22562538 | F32: =(D32-D31)/D31 -> 0.0033908488
B33: July | C33: 49607.69 | D33: 2717.85 | E33: =(C33-C32)/C32 -> 0.1692506 | F33: =(D33-D32)/D32 -> 0.23284223
B34: August | C34: 38604.12 | D34: 3836.75 | E34: =(C34-C33)/C33 -> -0.22181178 | F34: =(D34-D33)/D33 -> 0.41168571
B35: September | C35: 38863.31 | D35: 3099.1 | E35: =(C35-C34)/C34 -> 0.0067140502 | F35: =(D35-D34)/D34 -> -0.19225907
B36: October | C36: 53110.2 | D36: 1916.43 | E36: =(C36-C35)/C35 -> 0.36658972 | F36: =(D36-D35)/D35 -> -0.38161724
B37: November | C37: 36643.28 | D37: 2186.55 | E37: =(C37-C36)/C36 -> -0.31005193 | F37: =(D37-D36)/D36 -> 0.14094958
B38: December | C38: 39230.5 | D38: 2896.73 | E38: =(C38-C37)/C37 -> 0.070605579 | F38: =(D38-D37)/D37 -> 0.32479477
B41: 14. Identify Top 10% Product contributing to total sales (Pareto principle).
F43: {=_xlfn.LET(_xlpm.product,Data!G2:G501, _xlpm.Sales,Data!H2:H501, _xlpm.uniq_prod,_xlfn.UNIQUE(_xlpm.product), _xlpm.prod_sales,_xlfn.MAP(_xlpm.uniq_prod,_xlfn.LAMBDA(_xlpm.p,SUMIFS(_xlpm.Sales,_xlpm.product,_xlpm.p))), _xlpm.sorted,_xlfn.SORTBY(_xlfn.HSTACK(_xlpm.uniq_prod,_xlpm.prod_sales),_xlpm.prod_sales,-1), _xlpm.total_sales,SUM(_xlpm.prod_sales), _xlpm.cumulative,_xlfn.SCAN(0,INDEX(_xlpm.sorted,,2),_xlfn.LAMBDA(_xlpm.a,_xlpm.b,_xlpm.a+_xlpm.b)), _xlpm.percent,_xlpm.cumulative/_xlpm.total_sales, _xlpm.top10pct,_xlfn._xlws.FILTER(_xlpm.sorted,_xlpm.percent <=0.1), _xlfn.VSTACK({"Product","Sales"},_xlpm.top10pct))} -> Product | G43: Sales
F44: Monitor Model-975 | G44: 3206.52
F45: Laptop Model-983 | G45: 3034.31
F46: Pen Model-106 | G46: 2301.3
F47: Table Model-123 | G47: 1996
F48: Binder Model-791 | G48: 1995.65
F49: Chair Model-955 | G49: 1995.19
F50: Pen Model-180 | G50: 1991.69
F51: Bookcase Model-958 | G51: 1991.29
F52: Phone Model-832 | G52: 1990.61
F53: Stapler Model-820 | G53: 1981.38
F54: Bookcase Model-286 | G54: 1975.41
F55: Table Model-829 | G55: 1973.94
... F67: Table Model-669 | G67: 1922.9

Sheet Pviot(advance Analysts) 
A3: Row Labels | B3: Average of Profit
A4: January | B4: 87.595952
A5: February | B5: 88.137667
A6: March | B6: 67.932456
A7: April | B7: 83.760588
A8: May | B8: 59.380811
A9: June | B9: 51.210233
A10: July | B10: 55.466327
A11: August | B11: 85.261111
A12: September | B12: 83.759459
A13: October | B13: 35.489444
A14: November | B14: 72.885
A15: December | B15: 70.651951
A16: 6 | B16: 2.5
A17: Grand Total | B17: 68.19642

Sheet Dashboard Tasks (Visualization)
A1: Sales & Profit Analytics Dashboard

Sheet backend 
A3: Row Labels | B3: Sum of Sales | C3: Sum of Quantity
A4: January | B4: 43951.5 | C4: 225
A5: February | B5: 34016.74 | C5: 150
A6: March | B6: 52376.79 | C6: 308
A7: April | B7: 35133.75 | C7: 173
A8: May | B8: 34616.54 | C8: 201
A9: June | B9: 42426.91 | C9: 234
A10: July | B10: 49607.69 | C10: 267
A11: August | B11: 38604.12 | C11: 234
A12: September | B12: 38863.31 | C12: 183
A13: October | B13: 53110.2 | C13: 305
A14: November | B14: 36643.28 | C14: 176
A15: December | B15: 39230.5 | C15: 229
A16: Grand Total | B16: 498581.33 | C16: 2685
B26: Row Labels | C26: Sum of Sales
B27: East | C27: 123362.66
B28: North | C28: 123265.84
B29: South | C29: 132689.12
B30: West | C30: 119263.71
B31: Grand Total | C31: 498581.33
B36: Sum of Sales | C36: Average of Profit2 | D36: Count of Region | E36: Sum of Profit
B37: 498581.33 | C37: 68.36416 | D37: 500 | E37: 34182.08
B38: =GETPIVOTDATA("Sum of Sales",$B$36) -> 498581.33 | C38: =GETPIVOTDATA("Average of Profit2",$B$36) -> 68.36416 | D38: =GETPIVOTDATA("Count of Region",$B$36) -> 500 | E38: =GETPIVOTDATA("Sum of Profit",$B$36) -> 34182.08
C43: Column Labels
C44: Furniture | E44: Office Supplies | G44: Technology | I44: Total Sum of Sales | J44: Total Sum of Cost
C45: Sum of Sales | D45: Sum of Cost | E45: Sum of Sales | F45: Sum of Cost | G45: Sum of Sales | H45: Sum of Cost
C46: 164547.98 | D46: 153648.57 | E46: 167120.33 | F46: 156603.79 | G46: 166913.02 | H46: 154146.89 | I46: 498581.33 | J46: 464399.25
A52: Row Labels | B52: Sum of Quantity | C52: Sum of Sales
A53: Monitor Model-975 | B53: 16 | C53: 3206.52
A54: Laptop Model-983 | B54: 10 | C54: 3034.31
A55: Pen Model-106 | B55: 12 | C55: 2301.3
A56: Table Model-123 | B56: 10 | C56: 1996
A57: Binder Model-791 | B57: 3 | C57: 1995.65
A58: Chair Model-955 | B58: 7 | C58: 1995.19
A59: Pen Model-180 | B59: 3 | C59: 1991.69
A60: Bookcase Model-958 | B60: 2 | C60: 1991.29
A61: Phone Model-832 | B61: 5 | C61: 1990.61
A62: Stapler Model-820 | B62: 8 | C62: 1981.38
A63: Grand Total | B63: 76 | C63: 22483.94
C73: Sum of Profit | D73: Column Labels
...
